2025-03-06 11:41:22,759 [INFO] USER:raghav_anand s3_resource.py:40:validate_bucket_name LOG: Starting validating bucket name 'syndicate-education-platform-custom-sandbox-artifacts-sbox01'
2025-03-06 11:41:22,759 [INFO] USER:raghav_anand s3_resource.py:73:validate_bucket_name LOG: Finished validating bucket name 'syndicate-education-platform-custom-sandbox-artifacts-sbox01'
2025-03-06 11:41:22,759 [INFO] USER:raghav_anand helper.py:525:convert LOG: Stripping run_id:JAP-08,run_type:stm,type:user,user_id:e329fe5a from "," a bit..
2025-03-06 11:41:22,759 [INFO] USER:raghav_anand helper.py:529:convert LOG: Converting: run_id:JAP-08,run_type:stm,type:user,user_id:e329fe5a to dict..
2025-03-06 11:41:22,762 [INFO] USER:raghav_anand helper.py:541:convert LOG: Converted to such a dict: {'run_id': 'JAP-08', 'run_type': 'stm', 'type': 'user', 'user_id': 'e329fe5a'}
2025-03-06 11:41:24,493 [WARNING] USER:raghav_anand generator.py:76:generate_configuration_files LOG: The config_path property is not specified. The working directory is used
2025-03-06 11:41:24,494 [WARNING] USER:raghav_anand generator.py:93:generate_configuration_files LOG: The "project_path" property is not specified. The working directory will be used as a project path. To change the path, edit the syndicate.yml by path C:\Demo\task02\.syndicate-config-dev
2025-03-06 11:41:24,497 [INFO] USER:raghav_anand generator.py:155:generate_configuration_files LOG: Syndicate initialization has been completed. 
Set SDCT_CONF:
Unix: export SDCT_CONF="C:\Demo\task02\.syndicate-config-dev"
Windows: setx SDCT_CONF C:\Demo\task02\.syndicate-config-dev
2025-03-06 11:41:24,499 [INFO] USER:raghav_anand helper.py:330:timed LOG: Stage config, elapsed time: 0:00:01.737448
2025-03-06 11:41:33,712 [INFO] USER:raghav_anand handlers.py:106:syndicate LOG: Configuration used: C:\Demo\.syndicate-config-dev
2025-03-06 11:41:33,713 [ERROR] USER:raghav_anand decorators.py:136:wrapper LOG: sdct.conf does not exist inside C:\Demo\.syndicate-config-dev folder
2025-03-06 11:41:33,716 [ERROR] USER:raghav_anand decorators.py:137:wrapper LOG: Traceback (most recent call last):
  File "C:\Users\raghav_anand\AppData\Local\Programs\Python\Python313\Lib\site-packages\syndicate\core\decorators.py", line 134, in wrapper
    return_code = func(*args, **kwargs)
  File "C:\Users\raghav_anand\AppData\Local\Programs\Python\Python313\Lib\site-packages\syndicate\core\handlers.py", line 107, in syndicate
    initialize_connection()
    ~~~~~~~~~~~~~~~~~~~~~^^
  File "C:\Users\raghav_anand\AppData\Local\Programs\Python\Python313\Lib\site-packages\syndicate\core\__init__.py", line 106, in initialize_connection
    CONFIG = ConfigHolder(CONF_PATH)
  File "C:\Users\raghav_anand\AppData\Local\Programs\Python\Python313\Lib\site-packages\syndicate\core\conf\processor.py", line 63, in __init__
    self._init_conf_config(dir_path=dir_path)
    ~~~~~~~~~~~~~~~~~~~~~~^^^^^^^^^^^^^^^^^^^
  File "C:\Users\raghav_anand\AppData\Local\Programs\Python\Python313\Lib\site-packages\syndicate\core\conf\processor.py", line 92, in _init_conf_config
    raise AssertionError(
        'sdct.conf does not exist inside %s folder' % dir_path)
AssertionError: sdct.conf does not exist inside C:\Demo\.syndicate-config-dev folder
Traceback (most recent call last):
  File "C:\Users\raghav_anand\AppData\Local\Programs\Python\Python313\Lib\site-packages\syndicate\core\decorators.py", line 134, in wrapper
    return_code = func(*args, **kwargs)
  File "C:\Users\raghav_anand\AppData\Local\Programs\Python\Python313\Lib\site-packages\syndicate\core\handlers.py", line 107, in syndicate
    initialize_connection()
    ~~~~~~~~~~~~~~~~~~~~~^^
  File "C:\Users\raghav_anand\AppData\Local\Programs\Python\Python313\Lib\site-packages\syndicate\core\__init__.py", line 106, in initialize_connection
    CONFIG = ConfigHolder(CONF_PATH)
  File "C:\Users\raghav_anand\AppData\Local\Programs\Python\Python313\Lib\site-packages\syndicate\core\conf\processor.py", line 63, in __init__
    self._init_conf_config(dir_path=dir_path)
    ~~~~~~~~~~~~~~~~~~~~~~^^^^^^^^^^^^^^^^^^^
  File "C:\Users\raghav_anand\AppData\Local\Programs\Python\Python313\Lib\site-packages\syndicate\core\conf\processor.py", line 92, in _init_conf_config
    raise AssertionError(
        'sdct.conf does not exist inside %s folder' % dir_path)
AssertionError: sdct.conf does not exist inside C:\Demo\.syndicate-config-dev folder
